```swift
import Foundation

// Define a custom error type
enum MyError: Error {
    case invalidInput
    case operationFailed
}

// Define a function that throws an error
func doSomething() throws {
    // Check if the input is valid
    guard let input = readLine() else {
        throw MyError.invalidInput
    }

    // Attempt to perform an operation
    do {
        let result = try operation(input)
        print(result)
    } catch {
        throw MyError.operationFailed
    }
}

// Define a function that catches the error
func handleError() {
    do {
        try doSomething()
    } catch MyError.invalidInput {
        print("Invalid input")
    } catch MyError.operationFailed {
        print("Operation failed")
    } catch {
        print("An unknown error occurred")
    }
}

// Call the handleError function
handleError()
```

**Explanation:**

* The code defines a custom error type called `MyError` with two cases: `invalidInput` and `operationFailed`.
* The `doSomething()` function is defined as a throwing function, which means it can throw an error.
* Inside the `doSomething()` function, the code checks if the input is valid using the `guard let` statement. If the input is invalid, it throws the `MyError.invalidInput` error.
* The code then attempts to perform an operation using the `operation()` function, which is assumed to be a function that can throw an error.
* The `try` statement is used to catch the error thrown by the `operation()` function. If an error is thrown, the code catches it and throws the `MyError.operationFailed` error.
* The `handleError()` function is defined to catch the error thrown by the `doSomething()` function.
* Inside the `handleError()` function, the code uses a `do-catch` block to catch the error. If the error is `MyError.invalidInput`, it prints "Invalid input". If the error is `MyError.operationFailed`, it prints "Operation failed". If the error is any other type of error, it prints "An unknown error occurred".
* The code calls the `handleError()` function to handle the error thrown by the `doSomething()` function.